Workbook

Sheet 거래명세표
A1: 거 래 명 세 표 (공급자용)
A2: 날짜: 년 월 일
A3: 공 급 받 는 자 | B3: 등록번호: 603-81-70100 | E3: 공 급 자 | F3: 등록번호: 605-81-10092
B4: 상호: ㈜제일피엠씨 | C4: 성명: | F4: 상호: ㈜동명베아링 | H4: 성명: (인)
B5: 주소: 경남 창원시 성산구 창원대로 885 | F5: 주소: 경남 창원시 의창구 중앙대로 183
B6: 업태: 제조업 | F6: 업태: 도소매업
B7: 종목: 산업기계 부품 | F7: 종목: 베어링, 산업용품
A8: NO | B8: 코드번호 | C8: 품명 | D8: 규격 | E8: 수량 | F8: 단위 | G8: 단가 | H8: 공급가액 | I8: 비고
A9: 1 | C9: =IFERROR(VLOOKUP(B9,코드매핑!$A:$E,2,FALSE),"") | D9: =IFERROR(VLOOKUP(B9,코드매핑!$A:$E,3,FALSE),"") | F9: =IF(B9="","","EA") | G9: =IFERROR(VLOOKUP(B9,코드매핑!$A:$E,4,FALSE),"") | H9: =IF(AND(E9<>"",G9<>""),E9*G9,"") | I9: =IFERROR(VLOOKUP(B9,코드매핑!$A:$E,5,FALSE),"")
A10: 2 | C10: =IFERROR(VLOOKUP(B10,코드매핑!$A:$E,2,FALSE),"") | D10: =IFERROR(VLOOKUP(B10,코드매핑!$A:$E,3,FALSE),"") | F10: =IF(B10="","","EA") | G10: =IFERROR(VLOOKUP(B10,코드매핑!$A:$E,4,FALSE),"") | H10: =IF(AND(E10<>"",G10<>""),E10*G10,"") | I10: =IFERROR(VLOOKUP(B10,코드매핑!$A:$E,5,FALSE),"")
A11: 3 | C11: =IFERROR(VLOOKUP(B11,코드매핑!$A:$E,2,FALSE),"") | D11: =IFERROR(VLOOKUP(B11,코드매핑!$A:$E,3,FALSE),"") | F11: =IF(B11="","","EA") | G11: =IFERROR(VLOOKUP(B11,코드매핑!$A:$E,4,FALSE),"") | H11: =IF(AND(E11<>"",G11<>""),E11*G11,"") | I11: =IFERROR(VLOOKUP(B11,코드매핑!$A:$E,5,FALSE),"")
A12: 4 | C12: =IFERROR(VLOOKUP(B12,코드매핑!$A:$E,2,FALSE),"") | D12: =IFERROR(VLOOKUP(B12,코드매핑!$A:$E,3,FALSE),"") | F12: =IF(B12="","","EA") | G12: =IFERROR(VLOOKUP(B12,코드매핑!$A:$E,4,FALSE),"") | H12: =IF(AND(E12<>"",G12<>""),E12*G12,"") | I12: =IFERROR(VLOOKUP(B12,코드매핑!$A:$E,5,FALSE),"")
A13: 5 | C13: =IFERROR(VLOOKUP(B13,코드매핑!$A:$E,2,FALSE),"") | D13: =IFERROR(VLOOKUP(B13,코드매핑!$A:$E,3,FALSE),"") | F13: =IF(B13="","","EA") | G13: =IFERROR(VLOOKUP(B13,코드매핑!$A:$E,4,FALSE),"") | H13: =IF(AND(E13<>"",G13<>""),E13*G13,"") | I13: =IFERROR(VLOOKUP(B13,코드매핑!$A:$E,5,FALSE),"")
A14: 6 | C14: =IFERROR(VLOOKUP(B14,코드매핑!$A:$E,2,FALSE),"") | D14: =IFERROR(VLOOKUP(B14,코드매핑!$A:$E,3,FALSE),"") | F14: =IF(B14="","","EA") | G14: =IFERROR(VLOOKUP(B14,코드매핑!$A:$E,4,FALSE),"") | H14: =IF(AND(E14<>"",G14<>""),E14*G14,"") | I14: =IFERROR(VLOOKUP(B14,코드매핑!$A:$E,5,FALSE),"")
A15: 7 | C15: =IFERROR(VLOOKUP(B15,코드매핑!$A:$E,2,FALSE),"") | D15: =IFERROR(VLOOKUP(B15,코드매핑!$A:$E,3,FALSE),"") | F15: =IF(B15="","","EA") | G15: =IFERROR(VLOOKUP(B15,코드매핑!$A:$E,4,FALSE),"") | H15: =IF(AND(E15<>"",G15<>""),E15*G15,"") | I15: =IFERROR(VLOOKUP(B15,코드매핑!$A:$E,5,FALSE),"")
A16: 8 | C16: =IFERROR(VLOOKUP(B16,코드매핑!$A:$E,2,FALSE),"") | D16: =IFERROR(VLOOKUP(B16,코드매핑!$A:$E,3,FALSE),"") | F16: =IF(B16="","","EA") | G16: =IFERROR(VLOOKUP(B16,코드매핑!$A:$E,4,FALSE),"") | H16: =IF(AND(E16<>"",G16<>""),E16*G16,"") | I16: =IFERROR(VLOOKUP(B16,코드매핑!$A:$E,5,FALSE),"")
A17: 9 | C17: =IFERROR(VLOOKUP(B17,코드매핑!$A:$E,2,FALSE),"") | D17: =IFERROR(VLOOKUP(B17,코드매핑!$A:$E,3,FALSE),"") | F17: =IF(B17="","","EA") | G17: =IFERROR(VLOOKUP(B17,코드매핑!$A:$E,4,FALSE),"") | H17: =IF(AND(E17<>"",G17<>""),E17*G17,"") | I17: =IFERROR(VLOOKUP(B17,코드매핑!$A:$E,5,FALSE),"")
A18: 공급가액 합계 | H18: =SUM(H9:H17)
A19: 세액 (10%) | H19: =IF(H18=0,"",INT(H18*0.1))
A20: 합 계 (원정) | H20: =IF(H18=0,"",H18+H19)
A22: 인수자: (인) | F22: 품질관리: (인)
A23: 인수일자: 년 월 일
A26: 거 래 명 세 표 (공급받는자용)
A27: =IF(A2="","",A2)
A28: =IF(A3="","",A3) | B28: =IF(B3="","",B3) | E28: =IF(E3="","",E3) | F28: =IF(F3="","",F3)
B29: =IF(B4="","",B4) | C29: =IF(C4="","",C4) | F29: =IF(F4="","",F4) | H29: =IF(H4="","",H4)
B30: =IF(B5="","",B5) | F30: =IF(F5="","",F5)
B31: =IF(B6="","",B6) | F31: =IF(F6="","",F6)
B32: =IF(B7="","",B7) | F32: =IF(F7="","",F7)
A33: =IF(A8="","",A8) | B33: =IF(B8="","",B8) | C33: =IF(C8="","",C8) | D33: =IF(D8="","",D8) | E33: =IF(E8="","",E8) | F33: =IF(F8="","",F8) | G33: =IF(G8="","",G8) | H33: =IF(H8="","",H8) | I33: =IF(I8="","",I8)
A34: =IF(A9="","",A9) | B34: =IF(B9="","",B9) | C34: =IF(C9="","",C9) | D34: =IF(D9="","",D9) | E34: =IF(E9="","",E9) | F34: =IF(F9="","",F9) | G34: =IF(G9="","",G9) | H34: =IF(H9="","",H9) | I34: =IF(I9="","",I9)
A35: =IF(A10="","",A10) | B35: =IF(B10="","",B10) | C35: =IF(C10="","",C10) | D35: =IF(D10="","",D10) | E35: =IF(E10="","",E10) | F35: =IF(F10="","",F10) | G35: =IF(G10="","",G10) | H35: =IF(H10="","",H10) | I35: =IF(I10="","",I10)
A36: =IF(A11="","",A11) | B36: =IF(B11="","",B11) | C36: =IF(C11="","",C11) | D36: =IF(D11="","",D11) | E36: =IF(E11="","",E11) | F36: =IF(F11="","",F11) | G36: =IF(G11="","",G11) | H36: =IF(H11="","",H11) | I36: =IF(I11="","",I11)
A37: =IF(A12="","",A12) | B37: =IF(B12="","",B12) | C37: =IF(C12="","",C12) | D37: =IF(D12="","",D12) | E37: =IF(E12="","",E12) | F37: =IF(F12="","",F12) | G37: =IF(G12="","",G12) | H37: =IF(H12="","",H12) | I37: =IF(I12="","",I12)
A38: =IF(A13="","",A13) | B38: =IF(B13="","",B13) | C38: =IF(C13="","",C13) | D38: =IF(D13="","",D13) | E38: =IF(E13="","",E13) | F38: =IF(F13="","",F13) | G38: =IF(G13="","",G13) | H38: =IF(H13="","",H13) | I38: =IF(I13="","",I13)
A39: =IF(A14="","",A14) | B39: =IF(B14="","",B14) | C39: =IF(C14="","",C14) | D39: =IF(D14="","",D14) | E39: =IF(E14="","",E14) | F39: =IF(F14="","",F14) | G39: =IF(G14="","",G14) | H39: =IF(H14="","",H14) | I39: =IF(I14="","",I14)
A40: =IF(A15="","",A15) | B40: =IF(B15="","",B15) | C40: =IF(C15="","",C15) | D40: =IF(D15="","",D15) | E40: =IF(E15="","",E15) | F40: =IF(F15="","",F15) | G40: =IF(G15="","",G15) | H40: =IF(H15="","",H15) | I40: =IF(I15="","",I15)
A41: =IF(A16="","",A16) | B41: =IF(B16="","",B16) | C41: =IF(C16="","",C16) | D41: =IF(D16="","",D16) | E41: =IF(E16="","",E16) | F41: =IF(F16="","",F16) | G41: =IF(G16="","",G16) | H41: =IF(H16="","",H16) | I41: =IF(I16="","",I16)
A42: =IF(A17="","",A17) | B42: =IF(B17="","",B17) | C42: =IF(C17="","",C17) | D42: =IF(D17="","",D17) | E42: =IF(E17="","",E17) | F42: =IF(F17="","",F17) | G42: =IF(G17="","",G17) | H42: =IF(H17="","",H17) | I42: =IF(I17="","",I17)
A43: =IF(A18="","",A18) | H43: =IF(H18="","",H18)
...

Sheet 코드매핑
A1: 코드번호 | B1: 품명 | C1: 규격 | D1: 단가 | E1: 비고
A2: 40040036401 | B2: BEARING | C2: RNA6906 | D2: 5800 | E2: 112DT PUMP
A3: 40040036402 | B3: BEARING | C3: 6000ZZ | D3: 1200 | E3: MOTOR
A4: 40040036403 | B4: BEARING | C4: 6001ZZ | D4: 1300 | E4: MOTOR
A5: 40040036404 | B5: BEARING | C5: 6002ZZ | D5: 1400 | E5: CONVEYOR
A6: 40040036405 | B6: BEARING | C6: 6003ZZ | D6: 1500 | E6: CONVEYOR
A7: 40040036406 | B7: BEARING | C7: 6004ZZ | D7: 1800 | E7: PUMP
A8: 40040036407 | B8: BEARING | C8: 6005ZZ | D8: 2200 | E8: PUMP
A9: 40040036408 | B9: BEARING | C9: 6006ZZ | D9: 2800 | E9: PUMP
A10: 40040036409 | B10: BEARING | C10: 6007ZZ | D10: 3500 | E10: GEARBOX
A11: 40040036410 | B11: BEARING | C11: 6008ZZ | D11: 4200 | E11: GEARBOX
A12: 40040036411 | B12: BEARING | C12: 6009ZZ | D12: 4800 | E12: GEARBOX
A13: 40040036412 | B13: BEARING | C13: 6010ZZ | D13: 5500 | E13: GEARBOX
... A222: 77040037010 | B222: BUSH | C222: DU 3010 | D222: 3500 | E222: PIVOT
